Workbook

Sheet RegulationM-B
A1: Regulation | C1: M-B
A2: Available Pokemon
A3: DEXNo | B3: Pokemon | C3: Form
A4: #0003 | B4: Venusaur | C4: -
A5: #0003 | B5: Venusaur | C5: Mega
A6: #0006 | B6: Charizard | C6: -
A7: #0006 | B7: Charizard | C7: Mega X
A8: #0006 | B8: Charizard | C8: Mega Y
A9: #0009 | B9: Blastoise | C9: -
A10: #0009 | B10: Blastoise | C10: Mega
A11: #0015 | B11: Beedrill | C11: -
A12: #0015 | B12: Beedrill | C12: Mega
A13: #0018 | B13: Pidgeot | C13: -
A14: #0018 | B14: Pidgeot | C14: Mega
... A24: #0038 | B24: Ninetales | C24: Alola
A25: =INDEX(Dex!A:A, MATCH(B25, Dex!B:B, 0)) -> #0045 | B25: Vileplume | C25: -
A26: #0059 | B26: Arcanine | C26: -
A27: #0059 | B27: Arcanine | C27: Hisui
A28: #0065 | B28: Alakazam | C28: -
A29: #0065 | B29: Alakazam | C29: Mega
A30: #0068 | B30: Machamp | C30: -
A31: #0071 | B31: Victreebel | C31: -
A32: #0071 | B32: Victreebel | C32: Mega
A33: #0080 | B33: Slowbro | C33: -
A34: #0080 | B34: Slowbro | C34: Galar
A35: #0080 | B35: Slowbro | C35: Mega
A36: #0094 | B36: Gengar | C36: -
A37: #0094 | B37: Gengar | C37: Mega
... A76: #0208 | B76: Steelix | C76: Mega
A77: =INDEX(Dex!A:A, MATCH(B77, Dex!B:B, 0)) -> #0211 | B77: Qwilfish | C77: -
A78: #0212 | B78: Scizor | C78: -
A79: #0212 | B79: Scizor | C79: Mega
A80: #0214 | B80: Heracross | C80: -
A81: #0214 | B81: Heracross | C81: Mega
A82: #0227 | B82: Skarmory | C82: -
A83: #0227 | B83: Skarmory | C83: Mega
A84: #0229 | B84: Houndoom | C84: -
A85: #0229 | B85: Houndoom | C85: Mega
A86: #0248 | B86: Tyranitar | C86: -
A87: #0248 | B87: Tyranitar | C87: Mega
...

Sheet SpeedTiersM-B
A1: Regulation - M-A | D1: Trick Room | F1: Max EVs | H1: Scarf / Single Boost | J1: Tailwind / Double Boost
A2: Pokemon | B2: Image | C2: Base Speed | D2: Min Speed | E2: Neutral | F2: Neutral +32 | G2: Max +32 | H2: Neutral +32 / +1 | I2: Max +32 / +1 | J2: Neutral +32 / +2 | K2: Max +32 / +2
A3: Abomasnow | C3: 60 | D3: 72 | E3: 80 | F3: 112 | G3: 123 | H3: 168 | I3: 184 | J3: 224 | K3: 246
A4: Abomasnow-Mega | C4: 30 | D4: 45 | E4: 50 | F4: 82 | G4: 90 | H4: 123 | I4: 135 | J4: 164 | K4: 180
A5: Absol | C5: 75 | D5: 85 | E5: 95 | F5: 127 | G5: 139 | H5: 190 | I5: 208 | J5: 254 | K5: 278
A6: Absol-Mega | C6: 115 | D6: 121 | E6: 135 | F6: 167 | G6: 183 | H6: 250 | I6: 274 | J6: 334 | K6: 366
A7: Aegislash | C7: 60 | D7: 72 | E7: 80 | F7: 112 | G7: 123 | H7: 168 | I7: 184 | J7: 224 | K7: 246
A8: Aerodactyl | C8: 130 | D8: 135 | E8: 150 | F8: 182 | G8: 200 | H8: 273 | I8: 300 | J8: 364 | K8: 400
A9: Aerodactyl-Mega | C9: 150 | D9: 153 | E9: 170 | F9: 202 | G9: 222 | H9: 303 | I9: 333 | J9: 404 | K9: 444
A10: Aggron | C10: 50 | D10: 63 | E10: 70 | F10: 102 | G10: 112 | H10: 153 | I10: 168 | J10: 204 | K10: 224
A11: Aggron-Mega | C11: 50 | D11: 63 | E11: 70 | F11: 102 | G11: 112 | H11: 153 | I11: 168 | J11: 204 | K11: 224
A12: Alakazam | C12: 120 | D12: 126 | E12: 140 | F12: 172 | G12: 189 | H12: 258 | I12: 283 | J12: 344 | K12: 378
A13: Alakazam-Mega | C13: 150 | D13: 153 | E13: 170 | F13: 202 | G13: 222 | H13: 303 | I13: 333 | J13: 404 | K13: 444
A14: Alcremie | C14: 64 | D14: 75 | E14: 84 | F14: 116 | G14: 127 | H14: 174 | I14: 190 | J14: 232 | K14: 254
... A313: Zoroark-Hisui | C313: 110 | D313: 117 | E313: 130 | F313: 162 | G313: 178 | H313: 243 | I313: 267 | J313: 324 | K313: 356

Sheet SpeedTiersM-A
A1: Regulation - M-A | D1: Trick Room | F1: Max EVs | H1: Scarf / Single Boost | J1: Tailwind / Double Boost
A2: Pokemon | B2: Image | C2: Base Speed | D2: Min Speed | E2: Neutral | F2: Neutral +32 | G2: Max +32 | H2: Neutral +32 / +1 | I2: Max +32 / +1 | J2: Neutral +32 / +2 | K2: Max +32 / +2
A3: Alakazam-Mega | C3: 150 | D3: 153 | E3: 170 | F3: 202 | G3: 222 | H3: 303 | I3: 333 | J3: 404 | K3: 444
A4: Aerodactyl-Mega | C4: 150 | D4: 153 | E4: 170 | F4: 202 | G4: 222 | H4: 303 | I4: 333 | J4: 404 | K4: 444
A5: Beedrill-Mega | C5: 145 | D5: 148 | E5: 165 | F5: 197 | G5: 216 | H5: 295 | I5: 324 | J5: 394 | K5: 432
A6: Greninja-Mega | C6: 142 | D6: 145 | E6: 162 | F6: 194 | G6: 213 | H6: 291 | I6: 319 | J6: 388 | K6: 426
A7: Dragapult | C7: 142 | D7: 145 | E7: 162 | F7: 194 | G7: 213 | H7: 291 | I7: 319 | J7: 388 | K7: 426
A8: Manectric-Mega | C8: 135 | D8: 139 | E8: 155 | F8: 187 | G8: 205 | H8: 280 | I8: 307 | J8: 374 | K8: 410
A9: Lopunny-Mega | C9: 135 | D9: 139 | E9: 155 | F9: 187 | G9: 205 | H9: 280 | I9: 307 | J9: 374 | K9: 410
A10: Delphox-Mega | C10: 134 | D10: 138 | E10: 154 | F10: 186 | G10: 204 | H10: 279 | I10: 306 | J10: 372 | K10: 408
A11: Gengar-Mega | C11: 130 | D11: 135 | E11: 150 | F11: 182 | G11: 200 | H11: 273 | I11: 300 | J11: 364 | K11: 400
A12: Jolteon | C12: 130 | D12: 135 | E12: 150 | F12: 182 | G12: 200 | H12: 273 | I12: 300 | J12: 364 | K12: 400
A13: Aerodactyl | C13: 130 | D13: 135 | E13: 150 | F13: 182 | G13: 200 | H13: 273 | I13: 300 | J13: 364 | K13: 400
A14: Talonflame | C14: 126 | D14: 131 | E14: 146 | F14: 178 | G14: 195 | H14: 267 | I14: 292 | J14: 356 | K14: 390
... A275: Torkoal | C275: 20 | D275: 36 | E275: 40 | F275: 72 | G275: 79 | H275: 108 | I275: 118 | J275: 144 | K275: 158

Sheet RegulationM-A
A1: Regulation | C1: M-A
A2: Available Pokemon
A3: DEXNo | B3: Pokemon | C3: Form
A4: #0003 | B4: Venusaur | C4: -
A5: #0003 | B5: Venusaur | C5: Mega
A6: #0006 | B6: Charizard | C6: -
A7: #0006 | B7: Charizard | C7: Mega X
A8: #0006 | B8: Charizard | C8: Mega Y
A9: #0009 | B9: Blastoise | C9: -
A10: #0009 | B10: Blastoise | C10: Mega
A11: #0015 | B11: Beedrill | C11: -
A12: #0015 | B12: Beedrill | C12: Mega
A13: #0018 | B13: Pidgeot | C13: -
A14: #0018 | B14: Pidgeot | C14: Mega
... A193: #0678 | B193: Meowstic | C193: F
A194: #0678 | B194: Meowstic
A195: #0678 | B195: Meowstic | C195: Mega
A196: #0681 | B196: Aegislash | C196: -
A197: #0683 | B197: Aromatisse | C197: -
A198: #0685 | B198: Slurpuff | C198: -
A199: #0693 | B199: Clawitzer | C199: -
A200: #0695 | B200: Heliolisk | C200: -
A201: #0697 | B201: Tyrantrum | C201: -
A202: #0699 | B202: Aurorus | C202: -
A203: #0700 | B203: Sylveon | C203: -
A204: #0701 | B204: Hawlucha | C204: -
A205: #0701 | B205: Hawlucha | C205: Mega
A206: #0702 | B206: Dedenne | C206: -
... A212: #0711 | B212: Gourgeist | C212: Large
A213: #0711 | B213: Gourgeist
A214: #0711 | B214: Gourgeist | C214: Small
A215: #0713 | B215: Avalugg | C215: -
A216: #0713 | B216: Avalugg | C216: Hisui
A217: #0715 | B217: Noivern | C217: -
A218: #0724 | B218: Decidueye | C218: -
A219: #0724 | B219: Decidueye | C219: Hisui
A220: #0727 | B220: Incineroar | C220: -
A221: #0730 | B221: Primarina | C221: -
A222: #0733 | B222: Toucannon | C222: -
A223: #0740 | B223: Crabominable | C223: -
...

Sheet Dex
A1: ID | B1: Pokemon | C1: Form | D1: BST | E1: Speed
A2: #0001 | B2: Bulbasaur | C2: - | D2: 318 | E2: 45
A3: #0002 | B3: Ivysaur | C3: - | D3: 405 | E3: 60
A4: #0003 | B4: Venusaur | C4: - | D4: 525 | E4: 80
A5: #0003 | B5: Venusaur | C5: Mega | D5: 625 | E5: 80
A6: #0004 | B6: Charmander | C6: - | D6: 309 | E6: 65
A7: #0005 | B7: Charmeleon | C7: - | D7: 405 | E7: 80
A8: #0006 | B8: Charizard | C8: - | D8: 534 | E8: 100
A9: #0006 | B9: Charizard | C9: Mega X | D9: 634 | E9: 100
A10: #0006 | B10: Charizard | C10: Mega Y | D10: 634 | E10: 100
A11: #0007 | B11: Squirtle | C11: - | D11: 314 | E11: 43
A12: #0008 | B12: Wartortle | C12: - | D12: 405 | E12: 58
A13: #0009 | B13: Blastoise | C13: - | D13: 530 | E13: 78
... A897: #0717 | B897: Yveltal | C897: - | D897: 680 | E897: 99
A898: #0718 | B898: Zygarde | C898: 10 | D898: 486 | E898: 115
A899: #0718 | B899: Zygarde | C899: Complete | D899: 708 | E899: 85
A900: #0718 | B900: Zygarde | C900: - | D900: 600 | E900: 95
A901: #0718 | B901: Zygarde | C901: Mega | D901: 778 | E901: 100
A902: #0719 | B902: Diancie | C902: - | D902: 600 | E902: 50
A903: #0719 | B903: Diancie | C903: Mega | D903: 700 | E903: 110
A904: #0720 | B904: Hoopa | C904: - | D904: 600 | E904: 70
A905: #0720 | B905: Hoopa | C905: Unbound | D905: 680 | E905: 80
A906: #0721 | B906: Volcanion | C906: - | D906: 600 | E906: 70
A907: #0722 | B907: Rowlet | C907: - | D907: 320 | E907: 42
A908: #0723 | B908: Dartrix | C908: - | D908: 420 | E908: 52
A909: #0724 | B909: Decidueye | C909: Hisui | D909: 530 | E909: 60
A910: #0724 | B910: Decidueye | C910: - | D910: 530 | E910: 70
... A1249: #1025 | B1249: Pecharunt | C1249: - | D1249: 600 | E1249: 88
